Workbook

Sheet 읽는 법
A1: KBTI 인간 코딩 — 시험 세트 180건 · 코더 B
A3: 무엇인가 | B3: LLM 코딩과 GDELT 코딩을 사람 기준으로 재기 위한 독립 코딩입니다. 두 분이 같은 기사를 따로 코딩하고, 먼저 사람끼리의 일치도를 냅니다. 그 값이 LLM 이 넘어야 할 천장입니다.
A4: 유일한 지침 | B4: 코드북 v1.1. 이 시트는 코드북을 대체하지 않습니다. 판단이 서지 않으면 코드북을 보시고, 그래도 없으면 메모에 남기세요.
A6: 어떻게 | B6: '코딩' 시트의 노란 칸만 채웁니다. 드롭다운이 있습니다.
B7: 제목과 두 단락만 읽고 판정합니다. 기사 원문을 찾아보지 않습니다.
B8: V1 이 '아니오'나 '판정불가'면 V2~V5 는 비워 둡니다.
B9: '코드 확인' 열은 자동입니다 — V5 에 고른 코드의 이름이 뜹니다. 손대지 마세요.
B10: '확신' 은 판정불가로 돌릴까 망설인 건에 '낮음' 을 답니다.
A12: 반드시 | B12: 판정불가를 아끼지 마세요. 억지로 고른 값이 일치도를 올리고 지수를 망칩니다.
B13: 애매한 건은 메모에 한 줄 남겨 주세요. 코드북을 고치는 근거가 됩니다.
B14: 다른 코더와 상의하지 않습니다. 상의하면 일치도가 측정값이 아니게 됩니다.
B15: GDELT 배정과 LLM 코딩은 일부러 넣지 않았습니다.
A17: 표본 | B17: 복원한 감사 로그 37일치에서 제목이 있는 고유 기사 1,748건 중 날짜 비례로 180건. 난수씨 20261021 고정.
B18: 코드북을 만들고 고칠 때 쓴 9월 20일·10월 3일 기사는 전부 뺐습니다.
B19: 제목만 있고 단락이 빈 기사가 31건 들어 있습니다. 모집단의 실제 모습이며, 코드북 9장대로 제목이 사건을 다 말하면 코딩합니다.
A21: 분량 | B21: 180건에 3시간 30분 안팎. 한 번에 끝낼 필요 없습니다.
A22: 진행 | B22: =COUNTA(코딩!F4:F183)&" / 180 건 완료" -> 0 / 180 건 완료

Sheet 코딩
A1: 노란 칸만 채웁니다. 3행은 형식을 보여 주는 예시이니 지우고 시작하세요.
A2: ID | B2: 날짜 | C2: 제목 | D2: 첫 단락 | E2: 둘째 단락 | F2: V1 관련 | G2: V2 상대국 | H2: V3 방향 | I2: V4 주제 | J2: V5 코드 | K2: 코드 확인 | L2: 확신 | M2: 메모
A3: 예시 | B3: 2026-09-24 | C3: North Korea fires two ballistic missiles off east coast | D3: North Korea has launched two short-range ballistic missiles towards the sea, South Korea's military says. | F3: 예 | G3: PRK | H3: threat | I3: 군사 | J3: 150 | K3: =IFERROR(INDEX(코드집!$B:$B,MATCH($J3,코드집!$A:$A,0)),"") -> EXHIBIT FORCE POSTURE | L3: 높음 | M3: R1 — 바다로 쏜 시험이므로 150, 190 아님
A4: 1 | B4: 2026-10-01 | C4: South Korea leader urges Pyongyang dialogue - World News | D4: South Korean President Lee Jae Myung delivers a speech during the 78th Armed Forces Day at a military base in Gyeryong on October 1, 2026. (AFP Photo) | E4: South Korean President Lee Jae Myung urged North Korea on Oct. 1 to return to dialogue, a day after Seoul ’s military demanded an apology over a blast in the Demilitarized Zone ( DMZ ) that severely injured three South Korean soldiers. | K4: =IFERROR(INDEX(코드집!$B:$B,MATCH($J4,코드집!$A:$A,0)),"")
A5: 2 | B5: 2026-09-21 | C5: N Korea fires 2 ballistic missiles off east coast - Oman Observer | D5: SEOUL: North Korea fired two short-range ballistic missiles into the sea off its eastern coast on Sunday, South Korea's military said, with the second flying more than 600 kilometres. The launches came days after Pyongyang reasserted its status as a nuclear-armed state and rejected a United Nations resolution demanding it halt its nuclear activities. South Korea's military said the first missile was launched at around 3:00 pm from the Wonsan area and flew around 450 kilometres into the East Sea, a body of water also called the Sea of Japan. "Our military detected an additional short-range ballistic missile launched from the Wonsan area of North Korea towards the East Sea at around 5:50 pm," South Korea's Joint Chiefs of Staff (JCS) said. The second missile "flew more than 600 kilometres, and South Korean and US authorities are conducting a detailed analysis to determine its exact specifications," it said. The JCS said South Korea, the United States and Japan had been "tracking and sharing relevant developments from the initial stage of the launch". Japan lodged a "stern protest" with North Korea over the launches, condemning them as a threat to regional peace and security, the Kyodo news agency cited the government as saying. South Korea's presidential National Security Office convened an emergency security meeting following the first launch and assessed its impact on national security, the presidential office said. The government called on Pyongyang to "immediately cease" its ballistic missile launches, describing Sunday's firings as a "grave act" that violated UN Security Council resolutions. The launches came eight days after North Korea fired multiple short-range ballistic missiles towards the East Sea as part of what it later described as a joint firepower drill. That exercise involved long-range artillery and missiles, with the weapons "hitting the targets with 100 per cent accuracy", state media reported. North Korea accused "hostile forces" of seeking to end the country's nuclear programme during this week's General Conference of the International Atomic Energy Agency (IAEA). A foreign ministry spokesperson said the IAEA resolution "has no effect on the DPRK's position as a nuclear weapons state", using the acronym for North Korea's official name. The North's status as a nuclear power is "guaranteed by the actual nuclear deterrent and irreversibly and permanently fixed by the supreme law of the state", the spokesperson said. Kim Yo Jong, the powerful sister of North Korean leader Kim Jong Un, recently said the country's nuclear-armed status was "absolute" and called those hoping for its denuclearisation "idiots". US President Donald Trump said in August that North Korea possessed 57 "very powerful" nuclear weapons, while South Korea has put the figure at between 80 and 120. — AFP | E5: SEOUL: North Korea fired two short-range ballistic missiles into the sea off its eastern coast on Sunday, South Korea's military said, with the second flying more than 600 kilometres. The launches came days after Pyongyang reasserted its status as a nuclear-armed state and rejected a United Nations resolution demanding it halt its nuclear activities. South Korea's military said the first missile was launched at around 3:00 pm from the Wonsan area and flew around 450 kilometres into the East Sea, a body of water also called the Sea of Japan. "Our military detected an additional short-range ballistic missile launched from the Wonsan area of North Korea towards the East Sea at around 5:50 pm," South Korea's Joint Chiefs of Staff (JCS) said. The second missile "flew more than 600 kilometres, and South Korean and US authorities are conducting a detailed analysis to determine its exact specifications," it said. The JCS said South Korea, the United States and Japan had been "tracking and sharing relevant developments from the initial stage of the launch". Japan lodged a "stern protest" with North Korea over the launches, condemning them as a threat to regional peace and security, the Kyodo news agency cited the government as saying. South Korea's presidential National Security Office convened an emergency security meeting following the first launch and assessed its impact on national security, the presidential office said. The government called on Pyongyang to "immediately cease" its ballistic missile launches, describing Sunday's firings as a "grave act" that violated UN Security Council resolutions. The launches came eight days after North Korea fired multiple short-range ballistic missiles towards the East Sea as part of what it later described as a joint firepower drill. That exercise involved long-range artillery and missiles, with the weapons "hitting the targets with 100 per cent accuracy", state media reported. North Korea accused "hostile forces" of seeking to end the country's nuclear programme during this week's General Conference of the International Atomic Energy Agency (IAEA). A foreign ministry spokesperson said the IAEA resolution "has no effect on the DPRK's position as a nuclear weapons state", using the acronym for North Korea's official name. The North's status as a nuclear power is "guaranteed by the actual nuclear deterrent and irreversibly and permanently fixed by the supreme law of the state", the spokesperson said. Kim Yo Jong, the powerful sister of North Korean leader Kim Jong Un, recently said the country's nuclear-armed status was "absolute" and called those hoping for its denuclearisation "idiots". US President Donald Trump said in August that North Korea possessed 57 "very powerful" nuclear weapons, while South Korea has put the figure at between 80 and 120. — AFP | K5: =IFERROR(INDEX(코드집!$B:$B,MATCH($J5,코드집!$A:$A,0)),"")
A6: 3 | B6: 2026-10-09 | C6: Пхеньян против планов Сеула оказать помощь КНДР l KBS WORLD Russian | D6: Политика Президент РК поздравил граждан с Днём корейской письменности 2026-10-09 12:22:28 | K6: =IFERROR(INDEX(코드집!$B:$B,MATCH($J6,코드집!$A:$A,0)),"")
A7: 4 | B7: 2026-10-20 | C7: Jutarnji list - Šire se neprovjerene vijesti o stanju Kim Jong-una, izvanredno se obratila njegova sestra | K7: =IFERROR(INDEX(코드집!$B:$B,MATCH($J7,코드집!$A:$A,0)),"")
A8: 5 | B8: 2026-09-22 | C8: [사설]윤곽 드러난 대미투자, 끝까지 수익성 확보해야 - 파이낸셜뉴스 | D8: 정부의 대미 전략투자 윤곽이 드러났다. 정부는 22일 국회에 투자 1호 사업으로 미국 텍사스 엔시날 가스복합발전소 건설을 추진하겠다고 보고했다. 미국 내 대형 원전 8기 건설과 알래스카 액화천연가스(LNG) 개발은 2·3호 협의 과제로 제시했다. 후속협상에서도 끝까지 국익을 최우선 기준으로 삼아야 할 것이다. | E8: 1호인 엔시날 가스발전에 대해 정부는 사업성을 검토한 결과 수익성이 충분히 있는 것으로 판단했다고 한다. 인공지능(AI) 데이터센터와 첨단 반도체 공장 등이 잇따라 들어서는 텍사스에서 전력 수요가 빠르게 증가하는 점도 긍정적이다. 총사업비 223억달러를 투입해 20년간 432억9000만~454억300만달러의 수입을 거둘 수 있어 원리금 회수가 가능하다는 게 정부의 분석이다. 처음부터 6.3GW를 한꺼번에 짓지 않고 1.4GW부터 시작해 실제 수요와 경제성을 확인하며 단계적으로 증설하는 방식도 위험을 낮추는 안전장치가 될 수 있다. | K8: =IFERROR(INDEX(코드집!$B:$B,MATCH($J8,코드집!$A:$A,0)),"")
A9: 6 | B9: 2026-09-25 | C9: Tajni transfer više nije tajan: Seul zamjerio Zelenskom kršenje dogovora | advance.hr | D9: Piše advance.hr | E9: Južnokorejski predsjednik Lee Jae-myung izrazio je nezadovoljstvo Volodimirom Zelenskim nakon što je ukrajinski predsjednik pred Općom skupštinom UN-a objavio da su dvojica sjevernokorejskih ratnih zarobljenika prebačena u Južnu Koreju. Lee tvrdi da su se Seul i Kijev dogovorili kako će transfer ostati tajan te je ukrajinsko kršenje dogovora nazvao "vrlo razočaravajućim" . | K9: =IFERROR(INDEX(코드집!$B:$B,MATCH($J9,코드집!$A:$A,0)),"")
A10: 7 | B10: 2026-09-17 | C10: North Korea launches missile salvo after US-South Korea-Japan drills | South China Morning Post | D10: The ballistic missiles, which flew about 250km, were fired despite Donald Trump’s recent push for talks with Kim Jong-un | E10: The missiles were launched at around 5.20am and flew about 250 km (155 miles), the JCS said in a statement, ‌adding that South Korean and US authorities were conducting a detailed analysis of their specifications. | K10: =IFERROR(INDEX(코드집!$B:$B,MATCH($J10,코드집!$A:$A,0)),"")
A11: 8 | B11: 2026-09-25 | C11: Trump s pompou přijal prezidenta Číny: Honosná státní večeře! Na řadě je Putin? | Blesk.cz | D11: Nejmocnější muž světa si zve další lídry supervelmocí. Ve čtvrtek hostil s velkou slávou čínského prezidenta, pozvání na prosinec teď dostal i ten ruský. Ten však zatím dává přednost jiné společnosti… | E11: Červený koberec, armádní uvítání s vojenskou kapelou, dělostřeleckou salvou a přeletem burácivých bombardérů B-1 – dohromady 479 mužů a žen v uniformách – či galavečeře s nejbohatšími muži světa jako Elon Musk a Jeff Bezos . Takové přivítání přichystal Donald Trump s Melanií po boku pro Si Ťin-pchinga a jeho první dámu Pcheng Li-jüan , jak vypočetl web rádia NPR . A to na oplátku za svou návštěvu Pekingu v polovině května. | K11: =IFERROR(INDEX(코드집!$B:$B,MATCH($J11,코드집!$A:$A,0)),"")
A12: 9 | B12: 2026-09-21 | C12: N. Korea launches 2 missiles toward sea | Northwest Arkansas Democrat-Gazette | D12: SEOUL, South Korea -- North Korea launched two short-range ballistic missiles toward the sea on Sunday, South Korea's military said, days after the North threatened to bolster its nuclear deterrent capabilities and respond to what it called U.S. hostilities. | E12: The launches were the latest in a series of weapons demonstrations by North Korea even after U.S. President Donald Trump scaled back a joint military exercise with South Korea last month in an apparent effort to revive diplomacy with the North's leader, Kim Jong Un. | K12: =IFERROR(INDEX(코드집!$B:$B,MATCH($J12,코드집!$A:$A,0)),"")
A13: 10 | B13: 2026-10-06 | C13: Южна Корея е доставила над 176 хил. тона гориво на Русия с танкери, част от които са под санкции ᐉ Новини от Fakti.bg - Свят | ФАКТИ.БГ | D13: 6 Октомври, 2026 16:34, обновена 6 Октомври, 2026 16:32 1 605 22 | E13: Южна Корея е доставила гориво на Русия с танкери, три от които са под санкции на Великобритания и Европейския съюз. Това се случва на фона на опитите на Москва да компенсира недостига на горива, причинен от прекъсвания в работата на нефтопреработвателните заводи, съобщава „Гардиън“, позовавайки се на анализ на пристанищни регистри и данни за проследяване на кораби, предава Фокус. | K13: =IFERROR(INDEX(코드집!$B:$B,MATCH($J13,코드집!$A:$A,0)),"")
A14: 11 | B14: 2026-09-19 | C14: South Korea, US discuss Seoul’s role in Middle East and investment pact | The Straits Times | D14: Sign up now: Get ST's newsletters delivered to your inbox | E14: US Secretary of State Marco Rubio (left) and South Korean Foreign Minister Cho Hyun during a trilateral meeting on the sidelines of the NATO leaders’ summit in Ankara on July 7. | K14: =IFERROR(INDEX(코드집!$B:$B,MATCH($J14,코드집!$A:$A,0)),"")
A15: 12 | B15: 2026-09-17 | C15: PM Han, AmCham seek deeper Korea-US investment ties - The Korea Herald | K15: =IFERROR(INDEX(코드집!$B:$B,MATCH($J15,코드집!$A:$A,0)),"")
A16: 13 | B16: 2026-10-12 | C16: North Korea fires multiple ballistic missiles, fourth test in a month | NK News | D16: Get behind the headlines | E16: North Korea fired multiple suspected ballistic missiles on Monday morning, according to Japanese and South Korean military authorities, the country’s fourth apparent missile test in the last month . | K16: =IFERROR(INDEX(코드집!$B:$B,MATCH($J16,코드집!$A:$A,0)),"")
A17: 14 | B17: 2026-10-16 | C17: "일본서 보던 옷이 여기 있네"…무신사 성수에 온 '조조타운' [현장] | D17: [아이뉴스24 구서윤 기자] 서울 성수동 무신사 스토어 성수에 들어서자 레이스와 리본으로 장식한 원피스부터 넉넉한 실루엣의 캐주얼웨어까지 일본 패션 브랜드의 옷들이 눈앞에 펼쳐졌다. | E17: 옷걸이마다 브랜드 특유의 색깔이 묻어났다. 국내 매장에서는 보기 드문 일본어 상품 설명과 엔화 가격표도 그대로 달려 있었다. 일본 여행 중 찾아가던 브랜드를 서울에서 직접 살펴보고 입어볼 수 있는 공간이었다. | K17: =IFERROR(INDEX(코드집!$B:$B,MATCH($J17,코드집!$A:$A,0)),"")
A18: 15 | B18: 2026-10-06 | C18: South Korea, US aligned on North Korea policy, denuclearisation of Korean Peninsula: FM Cho | D18: Seoul, Oct 6 : South Korean Foreign Minister Cho Hyun said Tuesday that South Korea and the United States are aligned in their North Korea policy and remain committed to the goal of denuclearising the Korean Peninsula. | E18: "Through multiple summit meetings, South Korea and the US have confirmed their aligned policy stance toward North Korea and their commitment to coordination," Cho said during a parliamentary audit of the foreign ministry. | K18: =IFERROR(INDEX(코드집!$B:$B,MATCH($J18,코드집!$A:$A,0)),"")
A19: 16 | B19: 2026-09-30 | C19: ‘Kim Jong Un a friend’: Trump's reasoning on why North Korea can have nuclear weapons but Iran cannot | World News | D19: US President Donald Trump has once again spotlighted his close relationship with North Korean leader Kim Jong Un. Trump made the remarks on Tuesday while answering a question about why North Korea could possess nuclear weapons while Iran was being prevented from acquiring them. | E19: “He happens to be a friend of mine. Kim Jong Un is a friend of mine,” the US President said. “He likes Trump…I’m about the only person in the entire world that he likes, and I like him. As long as I'm around, he's going to be fine. You know why? Because he respects me and he likes me.” | K19: =IFERROR(INDEX(코드집!$B:$B,MATCH($J19,코드집!$A:$A,0)),"")
A20: 17 | B20: 2026-10-09 | C20: FACT FOCUS: Trump says tariffs have brought more US auto factories. His numbers are off. | Business | dailygazette.com | D20: FILE - Cars are pictured on the assembly line at the BMW Spartanburg plant in Greer, S.C., October 19, 2022. | E20: DETROIT (AP) — As President Donald Trump travels the country to rally support for Republican candidates ahead of the midterm elections, he is touting his economic agenda and crediting GOP-backed tariffs with industry growth — including what he says are more vehicle manufacturing plants all over the country. | K20: =IFERROR(INDEX(코드집!$B:$B,MATCH($J20,코드집!$A:$A,0)),"")
A21: 18 | B21: 2026-09-17 | C21: De la autonomía en defensa a la cooperación industrial: la experiencia surcoreana y las nuevas posibilidades para América Latina | D21: El pasado mes de julio, el presidente Lee Jae Myung visitó sucesivamente Brasil , Chile y Argentina . En particular, la visita a Chile fue la primera visita oficial de un presidente surcoreano en 11 años, y ambos países acordaron ampliar la cooperación no solo en minerales críticos, energía, comercio e inversión, sino también en seguridad pública, defensa, infraestructura y asuntos marítimos. En este contexto, no basta con interpretar la cooperación en defensa entre Corea del Sur y América Latina únicamente como la aparición de un nuevo proveedor de sistemas de armas. Para comprender la industria de defensa surcoreana, conviene partir de una pregunta: ¿Por qué Corea del Sur comenzó a construir una industria de defensa propia? Esta pregunta guarda ciertos puntos de contacto con las preocupaciones actuales de Chile y de algunos países latinoamericanos que buscan reforzar simultáneamente sus capacidades de defensa, su base industrial y su autonomía tecnológica. Este artículo es la primera entrega de una serie destinada a presentar la industria de defensa surcoreana a los lectores de Infodefensa. En ella se examinará cómo Corea del Sur fue construyendo sus capacidades nacionales de defensa y qué orientaciones de cooperación internacional están emergiendo hoy tanto en los sistemas terrestres como en los nuevos ámbitos de seguridad. Una industria nacida de la necesidad Uno de los principales puntos de inflexión en el desarrollo de la industria de defensa surcoreana fue la doctrina Nixon de 1969. La reducción de las fuerzas estadounidenses en Corea asociada a aquella doctrina fue uno de los factores que impulsaron a Corea del Sur a reforzar de forma más sistemática su capacidad de defensa autónoma, un proceso que posteriormente se concretó en programas de modernización de las Fuerzas Armadas . La cuestión que afrontaba entonces Corea del Sur era clara. ¿Qué capacidades debía ser capaz de asegurar por sí misma, aun manteniendo su alianza? Por ello, la autonomía en defensa surcoreana se desarrolló como un proceso de ampliación de las responsabilidades y capacidades propias, manteniendo al mismo tiempo la alianza y la cooperación internacional. A partir de entonces, Corea del Sur continuó desarrollando su base industrial de defensa en paralelo con la modernización de sus fuerzas armadas. Esa acumulación de capacidades a lo largo de varias décadas condujo al desarrollo y a la proyección internacional de sistemas terrestres como el obús autopropulsado K9 , el carro de combate K2 y vehículos blindados como Tigon y Redback . K2 y K9: de la exportación a la cooperación industrial Uno de los casos más destacados de la expansión internacional de los sistemas terrestres surcoreanos es Polonia . En 2022, Corea del Sur y Polonia suscribieron acuerdos de cooperación en defensa que incluían, entre otros sistemas, carros de combate K2 y obuses autopropulsados K9. En acuerdos posteriores sobre el K2 se incorporaron planes para desarrollar la versión K2PL adaptada a las necesidades de las Fuerzas Armadas polacas y para ensamblar y producir localmente una parte significativa de los vehículos mediante la cooperación entre empresas de defensa surcoreanas y polacas. Esto muestra una ampliación del modelo de cooperación: desde la exportación tradicional de sistemas terminados hacia esquemas que incorporan una mayor participación de la industria local. La cooperación internacional vinculada al K9 también se ha ampliado. Hanwha Aerospace suministra este sistema a varios países de la OTAN , entre ellos Finlandia y Rumanía , y en febrero de 2026 inició en Rumanía la construcción de una instalación para la producción local del K9. Sin embargo, lo más relevante de estos casos es cómo combinar la adquisición de sistemas de armas con la participación de la industria local, la producción y el desarrollo de capacidades de apoyo logístico a largo plazo. Se trata también de una cuestión de política industrial para los países que buscan modernizar sus fuerzas armadas sin renunciar al mantenimiento o al desarrollo de su propia base industrial de defensa. Fidae 2026 y Tigon Este cambio también puede observarse en América Latina. Fidae 2026 , celebrada en Santiago de Chile en abril, reunió a 451 empresas de 35 países y se consolidó como una de las principales ferias latinoamericanas de los sectores aeroespacial, defensa y seguridad. En la feria, Hanwha presentó el obús autopropulsado K9, el sistema de lanzacohetes múltiple Chunmoo y el vehículo Tigon MCV . La información oficial de Fidae presentó al Tigon como un vehículo blindado multipropósito capaz de integrar diferentes sistemas de armas en función de los requisitos de misión. No obstante, más interesante que la propia plataforma Tigon fue la modalidad de cooperación entre una empresa surcoreana y una empresa española anunciada durante Fidae. Hanwha Aerospace e Indra Group firmaron en Fidae 2026 un memorando de entendimiento para proponer una solución conjunta al futuro programa de vehículos blindados del Ejército de Chile y ampliar posteriormente la cooperación hacia otros proyectos terrestres en América Latina. De acuerdo con la estructura de cooperación anunciada, Hanwha aporta la plataforma blindada Tigon, mientras que Indra aporta el Mission System Equipment que incluye capacidades de conectividad, conciencia situacional y C2 . Este caso demuestra que la cooperación en defensa entre Corea del Sur, España y América Latina no tiene por qué limitarse a un modelo en el que un país suministra un sistema terminado a otro. También es posible combinar una plataforma surcoreana con tecnologías españolas de sistemas de misión y adaptarlas a los requisitos operativos de Chile y de otros países latinoamericanos. La pregunta que plantea Chile La relevancia de este tipo de cooperación industrial también puede entenderse a partir de la propia política de defensa chilena. En documentos oficiales de 2026, el Ministerio de Defensa Nacional de Chile vinculó la defensa con la base productiva y tecnológica del país y planteó el fortalecimiento de la autonomía, la soberanía tecnológica y las capacidades polivalentes. Durante la inauguración de Fidae 2026, el Ministerio de Defensa chileno también destacó el fortalecimiento de la industria nacional de defensa y el desarrollo de capacidades espaciales propias, vinculando tecnología y soberanía. Esto no significa necesariamente que todos los sistemas de armas deban producirse de forma autónoma dentro del país. La cuestión se acerca más a cómo utilizar la cooperación internacional y, al mismo tiempo, asegurar las tecnologías esenciales y las capacidades propias de operación, mantenimiento y sostenimiento. La pregunta a la que Corea del Sur se enfrentó en el pasado presentaba ciertos elementos similares: no solo cómo adquirir los sistemas necesarios, sino también cómo operarlos, mantenerlos y convertirlos gradualmente en capacidades acumuladas dentro del propio país. Naturalmente, la experiencia surcoreana no puede trasladarse de manera mecánica a Chile ni a otros países latinoamericanos. Sin embargo, existe una cuestión compartida: encontrar un equilibrio adecuado entre la cooperación internacional y el fortalecimiento de las capacidades nacionales. Una nueva concepción de la autonomía en defensa Hoy el alcance de esta cuestión es mucho mayor. Si en la Corea del Sur de los años setenta uno de los principales objetivos de la autonomía en defensa era desarrollar fuerzas convencionales y establecer una base nacional para producir el equipo necesario, el entorno de seguridad actual exige algo más. Drones y sistemas no tripulados, ciberataques, guerra electrónica, amenazas contra las redes de comunicaciones y los datos, vulnerabilidades de los activos espaciales y crimen organizado transnacional están ampliando rápidamente el espectro de riesgos de seguridad. Estos cambios están ampliando también el propio concepto de capacidad de defensa. Ya no importa únicamente el rendimiento de plataformas tradicionales como carros de combate, vehículos blindados u obuses autopropulsados. Cada vez resulta más importante la capacidad de integrarlas eficazmente con C4I , inteligencia, vigilancia y reconocimiento, guerra electrónica, sistemas antidrones, ciberdefensa y redes de datos. Nuevas capacidades para América Latina Esta cuestión también es relevante para América Latina. No puede afirmarse que todos los países latinoamericanos sigan una misma política de seguridad. Sin embargo, las tendencias observadas en Fidae y en la reciente política de defensa chilena muestran una creciente atención no solo a las capacidades militares tradicionales, sino también al espacio, la ciberseguridad, los sistemas no tripulados, la defensa aérea y los radares. Por ello, la futura cooperación entre Corea del Sur y América Latina tampoco tiene por qué limitarse a plataformas terrestres tradicionales como el K9 o el Tigon. Existen posibilidades de ampliar la cooperación hacia ámbitos como C4I, inteligencia, vigilancia y reconocimiento, sistemas antidrones, guerra electrónica, ciberdefensa y procesamiento de información basado en inteligencia artificial. Más importante que el producto es la forma de cooperar Las condiciones históricas de Corea del Sur son diferentes de las de otros países y la trayectoria de su industria de defensa tampoco constituye un modelo universal que pueda reproducirse en cualquier lugar. No obstante, la experiencia de un país que partió de una fuerte dependencia del equipamiento y de la tecnología del exterior y que gradualmente amplió su propia base industrial de defensa y sus capacidades de desarrollo puede ofrecer un punto de referencia para países que buscan abordar simultáneamente la modernización militar y el fortalecimiento industrial. La estructura debe adaptarse a la base industrial, los requerimientos operativos, el nivel tecnológico y los objetivos de política pública de cada socio. De una preocupación común a la cooperación Lo que Corea del Sur puede compartir con los responsables de defensa y de industria de América Latina no se limita a determinados sistemas de armas. Tras la doctrina Nixon, Corea del Sur se enfrentó a una pregunta fundamental: ¿Cómo reforzar sus propias capacidades de defensa manteniendo al mismo tiempo la alianza y la cooperación internacional? Hoy el alcance de esa pregunta es todavía mayor. En un entorno en el que los Estados deben responder tanto a amenazas militares tradicionales como a riesgos cibernéticos, sistemas no tripulados, guerra electrónica y amenazas contra las cadenas de suministro y las infraestructuras críticas, el reto consiste en asegurar de manera sostenible las capacidades nacionales necesarias. En el proceso por el cual Chile y otros países latinoamericanos buscan respuestas adaptadas a sus propias circunstancias, Corea del Sur puede ser uno de sus socios de cooperación. La posibilidad de avanzar más allá de una relación Buyer-Seller hacia una Industrial and Security Partnership comienza precisamente aquí. Sobre el autor Hwang Jung-han es asesor de la Asociación Corea-América Latina y autor de «¿Por qué Chile ahora?», el primer libro coreano en presentar de manera integral la política, la economía, la sociedad y la cultura de Chile. Se desempeñó como ministro consejero y cónsul general en la Embajada de la República de Corea en Chile. | E21: El pasado mes de julio, el presidente Lee Jae Myung visitó sucesivamente Brasil , Chile y Argentina . En particular, la visita a Chile fue la primera visita oficial de un presidente surcoreano en 11 años, y ambos países acordaron ampliar la cooperación no solo en minerales críticos, energía, comercio e inversión, sino también en seguridad pública, defensa, infraestructura y asuntos marítimos. | K21: =IFERROR(INDEX(코드집!$B:$B,MATCH($J21,코드집!$A:$A,0)),"")
A22: 19 | B22: 2026-10-05 | C22: 북한의 눈치를 보는 게 그렇게 큰 문제일까 - 오마이뉴스 | K22: =IFERROR(INDEX(코드집!$B:$B,MATCH($J22,코드집!$A:$A,0)),"")
A23: 20 | B23: 2026-10-14 | C23: 국익·안보 중시를 事大 폄훼하고 北엔 굴종하는 李정부[사설] | 문화일보 | D23: 이재명 대통령이 13일 국무회의에서 “대한민국의 국익이 지켜지는 외교”를 강조하며 “국가 관계에 있어 굴종적 태도나 사대적 태도를 지양해야 한다”고 했다. 누가 어떤 굴종적·사대적 태도를 취하고 있다고 생각하는지 구체적으로 지칭하진 않았지만, 가깝게는 최근 한미동맹 불안 문제와 관련해 정동영·이종석 퇴진을 포함해 미국 측과 갈등 요인을 없애라는 요구 등을 겨냥한 것으로 해석된다. 더 멀리는, 진보 진영에서 거론해온 이승만 대통령이 전시 작전통제권을 미국에 넘긴 것, 박정희 대통령이 한일 수교를 결단한 것 등을 의식했을 수도 있을 것이다. | E23: 그러나 이 대통령의 굴종·사대는 궤변에 가깝다. 오히려 미국의 대북 정보 제한 조치 해소를 위한 인사 교체론이 제기되자 차단하려는 목적도 강해 보인다. 한미 연합 기밀 누출이 한미 갈등을 불렀다면 조사를 통해 정보 관리 실패 원인을 규명한 뒤 해법을 찾으면 된다. 그게 73년 동맹의 기본이다. 백악관이 “동맹 기준 준수”를 언급한 것도 그런 의미다. 한미 갈등을 해소하고 협력 틀을 만드는 것을 사대로 폄훼하면 안 된다. 그런 게 국익 외교다. | K23: =IFERROR(INDEX(코드집!$B:$B,MATCH($J23,코드집!$A:$A,0)),"")
A24: 21 | B24: 2026-10-14 | C24: [Deep dive] Lee’s core supporters can only take him so far | D24: The decline in President Lee Jae Myung’s approval rating appears to have stopped, at least for now. | E24: In a regular survey released on Sept. 30 by the Korea Society Opinion Institute, 38.5% of respondents gave Lee a positive job approval rating, while 57.8% gave him a negative rating. Two weeks earlier, the figures were 35.9% positive and 59.4% negative. | K24: =IFERROR(INDEX(코드집!$B:$B,MATCH($J24,코드집!$A:$A,0)),"")
A25: 22 | B25: 2026-09-21 | C25: Северна Корея изстреля две ракети, Южна Корея свика Съвета за нац... | D25: Редактор: Ивайло Александров | E25: Северна Корея е изстреляла балистична ракета с малък обсег, а по-късно и неидентифициран снаряд край източния си бряг в района на Вонсан, съобщава Reuters. Според японското министерство на отбраната, снарядът е паднал извън изключителната икономическа зона на Япония. | K25: =IFERROR(INDEX(코드집!$B:$B,MATCH($J25,코드집!$A:$A,0)),"")
A26: 23 | B26: 2026-09-26 | C26: SF 한인회, 비슬 무용단 초청 문화 행사 - 미주 한국일보 | D26: 판매세, 계속 올리는 것 능사 아니다 | E26: 또 다시 맞이한 ‘기나 긴 황혼녘의 투쟁’ | K26: =IFERROR(INDEX(코드집!$B:$B,MATCH($J26,코드집!$A:$A,0)),"")
A27: 24 | B27: 2026-10-06 | C27: North Korea warns of 'powerful counteraction' if South intrudes 'even a millimetre' into its territory | D27: Seoul, Oct 6 : North Korea on Tuesday warned of an "immediate and powerful counteraction" if South Korea intrudes even "a millimetre" into its territory, after Seoul signalled corresponding measures over a recent land mine blast at the inter-Korean border that it has blamed on Pyongyang. | E27: The North's foreign ministry issued the statement a day after the South's military concluded the mines planted by North Korea caused the September 21 blast on the southern side of the Demilitarised Zone (DMZ) that left two South Korean soldiers critically injured, Yonhap News Agency reported. | K27: =IFERROR(INDEX(코드집!$B:$B,MATCH($J27,코드집!$A:$A,0)),"")
A28: 25 | B28: 2026-09-25 | C28: 3 Na Hong-Jin Movies You Must See As Hope Hits Cinemas | D28: While the much-anticipated release of Avengers: Endgame Encore may be hogging the headlines this week, there is another wildly entertaining, kind of unwieldy, ridiculously ambitious near-three-hour-long sci-fi blockbuster that's got us really excited right now: Na Hong-jin's gonzo creature feature Hope . | E28: Heavily reported on as the most expensive South Korean movie ever made, Director Na's latest — which sees two police officers in a small town near the demilitarised zone between North and South Korea find themselves under attack from a mysterious creature — hits UK cinemas this week amid major hype and the promise of an experience that demands to be seen on the biggest screen possible. | K28: =IFERROR(INDEX(코드집!$B:$B,MATCH($J28,코드집!$A:$A,0)),"")
A29: 26 | B29: 2026-09-29 | C29: Zelenskiy'den çarpıcı iddia: Rusya’ya 10 bin Kuzey Kore askeri daha geliyor | Türkiye Gazetesi | D29: Ukrayna Devlet Başkanı Zelenskiy sosyal medya hesabından paylaştığı videolu mesajda, Rusya saflarında savaşan Kuzey Kore askerlerine ilişkin açıklamalarda bulundu. | E29: Zelenskiy, "Bugün Ukrayna Savunma İstihbaratından Rusya'nın bundan sonra planladığı önlemlerle ilgili bir rapor aldım. Aslında Ruslar ek seferberliğe çoktan başladı, çeşitli yollarla askere aldıkları insan sayısını artırıyorlar. Ayrıca yabancıların işe alımını artırmayı planlıyorlar. Bu ülkelerin hükümetlerinin buna karşı önlem alması önemlidir. İlgili tüm hükümetleri bilgilendireceğiz" ifadelerini kullandı. Zelenskiy, "Kuzey Kore birliklerinin Rusya'ya konuşlandırılmasıyla ilgili yeni verilere sahibiz. Şu anda Rus topraklarında 8 binden fazla Kuzey Kore askeri bulunuyor. Ayrıca 10 bin askerin daha konuşlandırılması için hazırlıklar sürüyor, bu askerler eğitimden geçirilmek ve daha sonra Rusya'ya gönderilmek üzere seçiliyor" dedi. | K29: =IFERROR(INDEX(코드집!$B:$B,MATCH($J29,코드집!$A:$A,0)),"")
A30: 27 | B30: 2026-09-28 | C30: 靑, 이례적 강경대응…“北 포로 韓행, 우크라가 먼저 비공개 요구” - 전자신문 | D30: 청와대가 북한군 포로 2명의 한국 송환 사실을 공개한 뒤 비공개 합의 자체를 부인한 우크라이나 정부에 공식 해명과 사과를 요구했다. 비공개는 당초 우크라이나 측의 요청이었다며 협상 경위를 공개하고 합의 부인이 양국 간 신뢰를 심각하게 훼손했다며 추가 조치 검토까지 예고했다. 국내에서 이재명 대통령의 거짓말 논란으로 번진 사안에 대해 우크라이나 측의 책임을 강조하며 강경 대응에 나선 셈이다. 성기홍 청와대 홍보소통수석은 27일(한국시간) 입장문을 통해 “ 우크라이나 정부 측의 합의에 위반한 일방적 공개와 이에 이은 비공개합의 사실이 없다는 허위 공보에 대해 강력한 유감을 표하며, 공식적인 해명과 사과를 요구한다”고 말했다. 앞서 볼로디미르 젤렌스키 우크라이나 대통령은 23일(현지시간) 미국 뉴욕에서 열린 유엔총회에서 북한군 포로 2명의 한국 송환 사실을 공개했다. 이후 논란이 일자 이 대통령은 X(구 트위터)를 통해 “(우크라이나가) 비공개 합의를 어겼다”고 반박했다. 하지만 우크라이나 대통령실의 한 소식통은 언론에 “비밀 유지를 약속하지 않았다”고 흘리는 등 진실 공방 양상이 빚어졌다. 동시에 국내에서도 북한군 포로 한국 송환의 비공개 여부를 두고 정치적 공방이 일었다. 이 대통령의 미국 뉴욕·멕시코 순방에 동행했던 성 수석은 입장문을 통해 그동안의 협상 과정을 대거 공개했다. 순방에 함께했던 청와대 핵심급 참모가 한국 도착 직후 입장문을 낸 것도 모자라 협상 과정을 상세하게 설명하는 것은 다소 이례적이라는 평가가 나온다. 청와대의 기조가 강경대응으로 해석되는 이유다. 청와대는 북한군 포로의 한국행 비공개는 우크라이나 정부의 요청에 따른 것이라고 강조했다. 러시아와의 협상 과정에서 북한군 포로를 거래 대상으로 활용할 기회를 포기했다는 자국 내 비판을 우려했다는 취지다. 성 수석은 “북한군 포로의 한국 송환 문제는 국제적으로나 국내적으로 안보, 외교, 국방 및 인권에 관한 매우 민감한 문제로 오랫동안 치밀하게 논의되어온 사안”이라며 “ 우크라이나 정부는 그동안 우리측과 수차례 다양한 경로를 통해 포로송환 문제를 협의하며 협의 과정에서 '한국송환 시 다수의 자국 포로들과 교환할 기회를 포기했다는 국내 비난여론이 있을 수 있는 등 매우 민감한 사안이니 한국 송환사실을 비공개하자'며 보안을 요구했다”고 설명했다. 또 “ 우리측 역시 포로 당사자와 가족들의 안전문제와 외교 안보 등 여러 측면을 고려해 비공개에 합의하고 송환 절차를 진행했다. 그런데 우크라이나 정부가 북한군 포로송환 문제에 있어 충분한 사전설명이나 구체협의 없이 일방적으로 금번 유엔총회에서 대통령 연설을 통해 북한군 포로의 한국행을 전격공개했다”고 부연했다. 특히 “ 이에 따라 국내에서 불필요한 논란이 발생하므로 이재명 대통령이 비공개 합의에 반한 공개에 대해 아쉬움을 표현하자, 이번에는 우크라이나 대통령실이 협의나 양해는 물론 사전통보조차 없이 사실과 다르게 '비공개를 합의한 적이 없다'고 발표했다. 이에 따라 국내에서는 대통령의 거짓말 논란까지 발생하고 있다”고 비판했다. 청와대는 이번 논란의 책임이 우크라이나에 있다는 입장을 다시 강조했다. 또 공식적인 해명·사과와 함께 추가적인 조치를 검토하겠다고 했다. 성 수석은 “ 우크라이나 측이 양국간 비공개합의를 어기고 사전 협의는 물론 통보조차 없이 일방적으로 공개한 것도 매우 중대한 문제지만, 우리 대통령의 사실에 기반한 정당한 공개발언에 대해 우크라이나 대통령실 공보실이 비공개 합의가 없었다는 거짓사실을 발표한 것은 양국정부간 신뢰를 심각하게 훼손하고, 양국의 우호 관계에 심대한 지장을 초래하는 행위”라고 강조했다. 또 “이 문제에 대해 추가적으로 필요한 조치를 검토 중”이라고 언급했다. 아울러 사실을 왜곡해 정쟁으로 삼는 일부 정치인들에 대해서도 경고의 메시지를 냈다. 성 수석은 “ 국내 일부 인사들이 우크라이나 정부측의 잘못을 지적하기보다 국익에 관계된 민감한 외교 안보 사안을 정쟁화하며 부당한 우크라이나측 행위를 두둔하며 국익을 훼손하는 것에 대해 깊은 유감을 표시한다. 확인되지 않은 허위주장이나 사실과 다른 주장을 삼가 주시도록 요청드린다”고 밝혔다. 최기창 기자 mobydic@etnews.com | K30: =IFERROR(INDEX(코드집!$B:$B,MATCH($J30,코드집!$A:$A,0)),"")
A31: 28 | B31: 2026-10-06 | C31: South Korean fuel shipments help Russia ease fuel crisis during Ukraine strikes | The Jerusalem Post | K31: =IFERROR(INDEX(코드집!$B:$B,MATCH($J31,코드집!$A:$A,0)),"")
A32: 29 | B32: 2026-09-25 | C32: "С большой помпой, но без прорывных результатов": В Восточной и Юго-Восточной Азии оценили итоги американо-китайского саммита - Российская газета | D32: Корейская пресса прежде всего обращает внимание на разрыв между масштабом приема Си и довольно скромными практическими результатами. "Ёнхап" сформулировал это практически предельно жестко: "Упаковка - пышный церемониал, но содержание встречи осталось скрытым"; кроме двухмесячного продления торгового перемирия заметного прогресса по Тайваню, ИИ и другим спорным вопросам агентство пока не видит. | E32: Более содержательную оценку сегодня дал сеульский East Asia Institute. Профессор Сеульского национального университета Чон Чжэ Сон считает важным само сохранение дипломатического канала и торгового перемирия, однако предупреждает: фундаментальное американо-китайское противостояние никуда не исчезло. Поэтому для Южной Кореи практический вывод - не воспринимать заявления Белого дома как окончательную стабилизацию и продолжать диверсифицировать цепочки поставок, особенно в технологическом секторе и критических материалах. | K32: =IFERROR(INDEX(코드집!$B:$B,MATCH($J32,코드집!$A:$A,0)),"")
A33: 30 | B33: 2026-09-16 | C33: KHSC gets $100,000 from car company's campaign - Kingston Whig | The Napanee Guide | D33: Kingston Health Sciences Centre is getting a $100,000 boost for pediatric cancer care from an automotive company’s national campaign, it was announced Tuesday at Kingston General Hospital. | E33: It’s the second year KHSC has received a grant through the Hyundai Hope on Wheels charitable foundation, which is distributing $4.1 million to 16 pediatric hosptials this year, up $100,000 from its inaugural year in 2025. | K33: =IFERROR(INDEX(코드집!$B:$B,MATCH($J33,코드집!$A:$A,0)),"")
A34: 31 | B34: 2026-10-19 | C34: 박완수 지사 “고용률 하락, 경남 경제 전반 진단 해야” :: 경남신문 | D34: 속보= 경남의 고용률과 취업자 수가 지난해 같은 달보다 감소한 가운데 박완수 경남도지사가 고용을 비롯한 지역경제 지표 전반에 대한 종합적인 진단을 지시했다.(19일 1면) | E34: 박 지사는 19일 오전 도청에서 열린 실국본부장회의에서 최근 발표된 경남 9월 고용동향과 관련해 “전년도 9월 고용률이 워낙 높았기 때문에 전년 동기 대비 기저효과도 있다”면서도 “현재 시점에서 경남의 고용률과 취업자 수를 비롯한 경제지표 전반에 대해 한국은행이나 유관기관과 함께 흐름과 추세를 진단하고 분석해 볼 필요가 있다”고 강조했다. 이어“취업률뿐만 아니라 다른 부분도 전반적으로 점검해 어떤 문제가 있는지 살펴봐 달라”고 주문했다. 국가데이터처 동남지방데이터청이 발표한 ‘2026년 9월 경상남도 고용동향‘에 따르면 경남의 고용률은 63.5%로 지난해 같은 달보다 0.6%p 하락했다. 취업자 수는 181만5000명으로 8000명 감소했다. 반면 실업률은 1.9%로 0.5%p 상승했고, 실업자는 3만6000명으로 1만명 증가했다. | K34: =IFERROR(INDEX(코드집!$B:$B,MATCH($J34,코드집!$A:$A,0)),"")
A35: 32 | B35: 2026-09-21 | C35: CJ제일제당, AI 시대 맞춤형 채용 컨퍼런스 ‘CJ 언바운드’ 개최... 1000명 몰렸다 | D35: CJ제일제당이 AI 시대에 맞춘 대규모 통합 채용 컨퍼런스를 개최하며 인재 확보 방식을 전면 개편했다. 기존의 일방향 설명회에서 벗어나 지원자가 직접 직무를 체험하고 현직자와 소통하는 '쌍방향 채용'으로 전환한 것이다. | E35: 21일 CJ제일제당은 지난 18일 서울 중구 CJ인재원에서 신입사원 채용 컨퍼런스 'CJ 언바운드(UNBOUND)'를 개최했다고 밝혔다. 사전 신청 첫날에만 1,000여 명이 몰릴 정도로 취업준비생들의 뜨거운 반응을 얻은 이번 행사에는 최종 추첨을 통해 선정된 300명이 참가했다. | K35: =IFERROR(INDEX(코드집!$B:$B,MATCH($J35,코드집!$A:$A,0)),"")
A36: 33 | B36: 2026-10-12 | C36: North Korea fires missiles days after South Koreaâs hypersonic test | D36: SEOUL, Oct 12 (Reuters) - North Korea fired multiple ballistic missiles toward the sea off its east coast on Monday, South Koreaâs military said, marking Pyongyangâs fourth launch in a month and following Seoulâs recent test of a hypersonic missile. | E36: By Heejin Kim and Joyce Lee The ballistic missiles, whichappeared to be of different types, were fired at around 9:20 a.m. local time (0020 GMT) from near Pyongyang, and one type flew more than 900 km (559 miles), South Korea's Joint Chiefs of Staff said. Earlier, Japan's coast guard said North Korea had fired two unidentified projectiles, believed to be ballistic missiles, adding that both appeared to have already fallen. South Korea's National Security Office convened an emergency meeting, where it condemned the missile launches as violations of United Nations Security Council resolutions and urged an immediate stop. North Korea has been under UN sanctions since 2006, aimed at halting Pyongyang's development of nuclear weapons and ballistic missiles. The latest launches come at a time when tensions have been rising between the two Koreas in recent weeks amid weapons tests by both countries. Last week, South Korean President Lee Jae Myung oversaw the country's first test-firing of a hypersonic missile , a rare public showcasing of a missile test by a South Korean president. Monday's missile launches by North Korea appeared to be "a show of force in response to the successful test launch of our hypersonic missile, as well as an intentional demonstration of missile capabilities," a spokesperson for South Korea's Joint Chiefs of Staff said. North Korea last fired a ballistic missile on October 3 , with state media KCNA saying it was a hypersonic missile tested under the supervision of leader Kim Jong Un . The tests followed a border mine blast last month that wounded three South Korean soldiers. Seoul said the landmines had been planted by North Korea and demanded an apology, but Pyongyang has dismissed this and accused South Korea of provocation. Pyongyang has conducted missile tests on more than 10 occasions this year, including four in the last month. The unusually frequent tests indicate Pyongyang wanted to increase its leverage ahead of a potential summit between leader Kim and US President Donald Trump, said Song Seong-jong, a professor at Daejeon University in Seoul and a former South Korean Defence Ministry official. "They definitely need to raise the value of their status before meeting Trump," Song said. (Reporting by Heejin Kim and Joyce Lee in Seoul, Anton Bridge in TokyoEditing by Ed Davies) | K36: =IFERROR(INDEX(코드집!$B:$B,MATCH($J36,코드집!$A:$A,0)),"")
A37: 34 | B37: 2026-10-16 | C37: Cât de departe poate merge Rusia: Volodimir Zelenski dezvălui planul lui Vladimir Putin | K37: =IFERROR(INDEX(코드집!$B:$B,MATCH($J37,코드집!$A:$A,0)),"")
A38: 35 | B38: 2026-10-08 | C38: Why U.S. And European Companies Are Investing In Asia | D38: Forbes Councils Member. | E38: Anoma Baste I MCR I Director Global Studio I Space Matrix. | K38: =IFERROR(INDEX(코드집!$B:$B,MATCH($J38,코드집!$A:$A,0)),"")
A39: 36 | B39: 2026-10-10 | C39: These 4 Android phone brands you forgot about are still making phones | D39: In the early days of Android, it seemed like every other week we'd see a completely brand-new phone from an established tech giant. Everyone was taking a stab at it. | E39: But as Android matured, a select handful of brands became the go-to choices for most buyers, namely Samsung, Google Pixel, and Motorola, while almost every other brand disappeared from the discourse. Well, as it turns out, many of those brands you think disappeared over the years are actually still making phones today, and some of them are surprisingly good. | K39: =IFERROR(INDEX(코드집!$B:$B,MATCH($J39,코드집!$A:$A,0)),"")
A40: 37 | B40: 2026-10-02 | C40: Сеул предложи на Пхенян преговори за границата | D40: 2 Октомври, 2026 06:55 1 808 2 | E40: Република Корея предложи на Северна Корея да започнат преговори за уточняване и повторно измерване на Военната демаркационна линия, разделяща двете държави. Инициативата беше отправена от министъра на обединението Чун Дон-йон на фона на напрежението след взрива на мина в Демилитаризираната зона. | K40: =IFERROR(INDEX(코드집!$B:$B,MATCH($J40,코드집!$A:$A,0)),"")
...

Sheet 코드집
A1: 코드 | B1: CAMEO 공식 명칭 | C1: Goldstein
A2: 010 | B2: MAKE PUBLIC STATEMENT | C2: 0
A3: 020 | B3: APPEAL | C3: 3
A4: 030 | B4: EXPRESS INTENT TO COOPERATE | C4: 4
A5: 040 | B5: CONSULT | C5: 1
A6: 050 | B6: ENGAGE IN DIPLOMATIC COOPERATION | C6: 3.5
A7: 060 | B7: ENGAGE IN MATERIAL COOPERATION | C7: 6
A8: 070 | B8: PROVIDE AID | C8: 7
A9: 080 | B9: YIELD | C9: 5
A10: 090 | B10: INVESTIGATE | C10: -2
A11: 100 | B11: DEMAND | C11: -5
A12: 110 | B12: DISAPPROVE | C12: -2
A13: 120 | B13: REJECT | C13: -4
... A17: 160 | B17: REDUCE RELATIONS | C17: -4
A18: 170 | B18: COERCE | C18: 공표표 확인 요망
A19: 180 | B19: ASSAULT | C19: -9
A20: 190 | B20: FIGHT | C20: -10
A21: 200 | B21: USE UNCONVENTIONAL MASS VIOLENCE | C21: 공표표 확인 요망
A22: 016 | B22: Reject accusation, deny responsibility | C22: -2
A23: 025 | B23: Appeal to yield | C23: -0.3
A24: 045 | B24: Engage in mediation | C24: 5
A25: 046 | B25: Engage in negotiation | C25: 7
A26: 054 | B26: Grant diplomatic recognition | C26: 6
A27: 055 | B27: Apologize | C27: 7
A28: 057 | B28: Sign formal agreement | C28: 8
A29: 084 | B29: Return, release | C29: 7
A30: 085 | B30: Ease economic sanctions, boycott, embargo | C30: 7
A31: 087 | B31: De-escalate military engagement | C31: 9
A32: 0871 | B32: Declare truce, ceasefire | C32: 9
A33: 0874 | B33: Retreat or surrender militarily | C33: 10
... A36: 164 | B36: Halt negotiations | C36: -7
A38: 루트 20개 + 세부 15개. 목록에 없는 CAMEO 코드는 루트로 접는다 (111·112·115 -> 110, 154 -> 150, 193·194 -> 190).
